<?xml version="1.0"?>
<robot name ="crab">


    <link name="base_link">
    </link>
    <!-- COXA JOINT AND LINK-->

    <joint name="coxa_joint" type="revolute">
        <origin xyz="0 0 0" rpy="0.0 0.0 0.0"/>
        <parent link="base_link"/>
        <child link="coxa_link"/>
        <limit effort="250.0" velocity="10.0" lower="-3.14" upper="3.14" />
        <axis xyz="0 0 1"/>
    </joint>

    <link name="coxa_link">
        <visual>
            <origin xyz="0 0 0" rpy=" 0.0 0.0 0.0"/>
            <geometry>
                <cylinder length="0.015" radius="0.015"/>
            </geometry>
            <material name="blue"/>
        </visual>
    </link>


    <!-- MERUS JOINT AND JOINT-->
    <joint name="merus_joint" type="revolute">
        <origin xyz="0 0.015 0" rpy="-1.1 0.0 0.0"/>
        <parent link="coxa_link"/>
        <child link="merus_link"/>
        <limit effort="250.0" velocity="10.0" lower="-3.14" upper="3.14" />            
        <axis xyz="1 0 0"/>
    </joint>

    <link name="merus_link">
        <visual>
            <origin xyz="0.0 0.0 0.1" rpy="0.0 0.0 0.0"/>
            <geometry>
                <cylinder length="0.2" radius="0.015"/>
            </geometry>
            <material name="blue"/>
        </visual>
    </link>     


    <!-- CARPUS JOINT AND LINK-->

    <joint name="carpus_joint" type="revolute">
        <origin xyz="0 0 0.215" rpy="-1.57 0.0 0.0"/>
        <parent link="merus_link"/>
        <child link="carpus_link"/>
        <limit effort="250.0" velocity="10.0" lower="-3.14" upper="3.14" />
        <axis xyz="1 0 0"/>
    </joint>

    <link name="carpus_link">
        <visual>
            <origin xyz="0 0 0.04" rpy="0.0 0.0 0.0"/>
            <geometry>
                <cylinder length="0.08" radius = "0.015"/>
            </geometry>
            <material name="pink"/>
        </visual> 
    </link>


    <!-- MANUS JOINT AND LINK -->
    <joint name="manus_joint" type="revolute">
        <origin xyz="0 0 0.08" rpy="-0.087 0.0 0.0"/>
        <parent link="carpus_link"/>
        <child link="manus_link"/>
        <limit effort="250.0" velocity="10.0" lower="-3.14" upper="3.14" />
        <axis xyz="0 1 0"/>
    </joint>

    <link name="manus_link">
        <visual>
            <origin xyz="0.0 0.0 0.07" rpy="0.0 0.0 0.0"/>
            <geometry>
                <cylinder length="0.14" radius = "0.015"/>
            </geometry>
            <material name="blue"/>
        </visual>
    </link>



    <!-- DACTYL JOINT AND LINK-->

    <joint name="dactyl_joint" type="fixed">
        <origin xyz="0.0 0.0 0.14" rpy="0.0 0.0 0.0"/>
        <parent link="manus_link"/>
        <child link="dactyl_link"/>
    </joint>


    <link name="dactyl_link">
        <visual>
            <origin xyz="0 0 0.035" rpy="0.0 0.0 0.0"/>
            <geometry>
                <cylinder length="0.07" radius = "0.015"/>
            </geometry>
            <material name="yellow"/>
        </visual>
    </link>


    <joint name="end" type="fixed">
        <parent link="dactyl_link"/>
        <child link="end_link"/>
        <origin rpy="0 0 0" xyz="0 0 0.07"/>
    </joint>

    <link name="end_link">
        <visual>
            <geometry>
                <box size="0.01 0.01 0.01" />
            </geometry>
            <origin rpy="0.0 0.0 0" xyz="0.0 0.0 0.0"/>
            <material name="pink"/>
        </visual>
    </link>  
    

    <material name="yellow">
        <color rgba="1 0.83 0 1"/>
    </material>
    
    <material name="blue">
        <color rgba="0.18 0.16 0.31 1"/>
    </material>
    
    <material name="pink">
        <color rgba="0.85 0.01 0.41 1"/>
    </material>
    
    <material name="purple">
        <color rgba="0.51 0.01 0.39 1"/>
    </material>


</robot>