<?xml version="1.0"?>
<robot xmlns:xacro="http://www.ros.org/wiki/xacro">

    <xacro:macro name="leg" params="suffix reflect Ox Oy Oz"> 

        <!-- -->

        <!-- COXA JOINT AND LINK-->

        <joint name="coxa_joint_${suffix}" type="revolute">
                <origin xyz="${Ox} ${Oy} ${Oz}" rpy="0.0 0.0 0.0"/>
                <parent link="body_link"/>
                <child link="coxa_link_${suffix}"/>
                <limit effort="250.0" velocity="10.0" lower="-3.14" upper="3.14" />
                <axis xyz="0 0 1"/>
                <dynamics damping="0.7"/>
        </joint>

        <link name="coxa_link_${suffix}">
            <visual>
                <origin xyz="${coxa_link_Ox} ${coxa_link_Oy} ${coxa_link_Oz}" rpy=" 0.0  ${coxa_link_Ry} 0.0"/>
                <geometry>
                    <cylinder length="${coxa_link_length}" radius="${coxa_link_radius}"/>
                </geometry>
                <material name="red"/>
            </visual>
        </link>

        <gazebo reference = "coxa_link_${suffix}">
            <material>Gazebo/Red</material>
        </gazebo>

        <!-- MERUS JOINT AND JOINT-->
        <joint name="merus_joint_${suffix}" type="revolute">
            <origin xyz="${reflect*merus_joint_Ox} ${merus_joint_Oy} ${merus_joint_Oz}" rpy="0.0 ${reflect*merus_joint_Ry} 0.0"/>
            <parent link="coxa_link_${suffix}"/>
            <child link="merus_link_${suffix}"/>
            <limit effort="250.0" velocity="10.0" lower="-3.14" upper="3.14" />            
            <axis xyz="0 1 0"/>
        </joint>

        <link name="merus_link_${suffix}">
            <visual>
                <origin xyz="${merus_link_Ox} ${merus_link_Oy} ${merus_link_Oz}" rpy="0.0 0.0 0.0"/>
                <geometry>
                    <cylinder length="${merus_link_length}" radius="${merus_link_radius}"/>
                </geometry>
                <material name="blue"/>
            </visual>
        </link>

        <gazebo reference = "coxa_link_${suffix}">
            <material>Gazebo/Blue</material>
        </gazebo>        


        <!-- CARPUS JOINT AND LINK-->

        <joint name="carpus_joint_${suffix}" type="revolute">
            <origin xyz="${carpus_joint_Ox} ${carpus_joint_Oy} ${carpus_joint_Oz}" rpy="0.0 ${reflect*carpus_joint_Ry} 0.0"/>
            <parent link="merus_link_${suffix}"/>
            <child link="carpus_link_${suffix}"/>
            <limit effort="250.0" velocity="10.0" lower="-3.14" upper="3.14" />
            <axis xyz="${reflect} 0 0"/>
            <dynamics damping="0.7"/>
        </joint>

        <link name="carpus_link_${suffix}">
            <visual>
                <origin xyz="${carpus_link_Ox} ${carpus_link_Oy} ${carpus_link_Oz}" rpy="0.0 0.0 0.0"/>
                <geometry>
                    <cylinder length="${carpus_link_length}" radius = "${carpus_link_radius}"/>
                </geometry>
                <material name="red"/>
            </visual>
        </link>

        <gazebo reference = "coxa_link_${suffix}">
            <material>Gazebo/Red</material>
        </gazebo>

        <!-- MANUS JOINT AND LINK -->
        <joint name="manus_joint_${suffix}" type="revolute">
            <origin xyz="${manus_joint_Ox} ${manus_joint_Oy} ${manus_joint_Oz}" rpy="0.0 ${reflect*manus_joint_Ry} 0.0"/>
            <parent link="carpus_link_${suffix}"/>
            <child link="manus_link_${suffix}"/>
            <limit effort="250.0" velocity="10.0" lower="-3.14" upper="3.14" />
            <axis xyz="0 1 0"/>
            <dynamics damping="0.7"/>
        </joint>

        <link name="manus_link_${suffix}">
            <visual>
                <origin xyz="0.0 0.0 ${manus_link_Oz}" rpy="0.0 0.0 0.0"/>
                <geometry>
                    <cylinder length="${manus_link_length}" radius = "${manus_link_radius}"/>
                </geometry>
                <material name="blue"/>
            </visual>
        </link>
    

        <gazebo reference = "coxa_link_${suffix}">
            <material>Gazebo/Blue</material>
        </gazebo>

        <!-- DACTYL JOINT AND LINK-->

        <joint name="dactyl_joint_${suffix}" type="fixed">
            <origin xyz="0.0 0.0 -${manus_link_length}" rpy="0.0 0.0 0.0"/>
            <parent link="manus_link_${suffix}"/>
            <child link="dactyl_link_${suffix}"/>
            <dynamics damping="0.7"/>
        </joint>

        <link name="dactyl_link_${suffix}">
            <visual>
                <origin xyz="${dactyl_link_Ox} ${dactyl_link_Oy} ${dactyl_link_Oz}" rpy="0.0 0.0 0.0"/>
                <geometry>
                    <sphere radius="${dactyl_radius}"/>
                </geometry>
                <material name="red"/>
            </visual>
        </link>

        <gazebo reference = "coxa_link_${suffix}">
            <material>Gazebo/Red</material>
        </gazebo>

    </xacro:macro>
</robot>